<?xml version="1.0"?>
<robot xmlns:xacro="http://www.ros.org/wiki/xacro">
	<xacro:macro name="niryo_one_description">
		<!-- Helper macro-->
		<xacro:include filename="$(find niryo_one_description)/urdf/v2/inc/create_link.xacro" />

		<!-- Properties -->

		<xacro:property name="distance_origin_shoulder_z" value="0.103" />
		<xacro:property name="distance_shoulder_arm_z" value="0.080" />
		<xacro:property name="distance_arm_elbow_x" value="0.210" />
		<xacro:property name="distance_arm_elbow_y" value="0.0" />
		<xacro:property name="distance_elbow_forearm_x" value="0.0415" />
		<xacro:property name="distance_elbow_forearm_y" value="0.030" />
		<xacro:property name="distance_forearm_wrist_z" value="0.180" />
		<xacro:property name="distance_wrist_hand_x" value="0.0164" />
		<xacro:property name="distance_wrist_hand_y" value="-0.0055" />
		<xacro:property name="distance_hand_tool" value="0.0073" />

		<xacro:property name="PI" value="3.14159265359" />

		<xacro:property name="limit_low_shoulder_rotation" value="-3.05433" />
		<xacro:property name="limit_up_shoulder_rotation" value="3.05433" />
		<xacro:property name="limit_low_arm_rotation" value="-1.57080" />
		<xacro:property name="limit_up_arm_rotation" value="0.640187" />
		<xacro:property name="limit_low_elbow_rotation" value="-1.397485" />
		<xacro:property name="limit_up_elbow_rotation" value="${PI/2}" />
		<xacro:property name="limit_low_forearm_rotation" value="-3.05433" />
		<xacro:property name="limit_up_forearm_rotation" value="3.05433" />
		<xacro:property name="limit_low_wrist_rotation" value="-1.74533" />
		<xacro:property name="limit_up_wrist_rotation" value="1.91986" />
		<xacro:property name="limit_low_hand_rotation" value="-2.57436" />
		<xacro:property name="limit_up_hand_rotation" value="2.57436" />


		<!-- Links -->
		<xacro:create_link
			link_name="base_link"
			xyz_offset="0 0 0"
			rpy_offset="0 0 0"
			mesh_package="niryo_one_description"
			mesh_name="base_link"
		/>

		<xacro:create_link
			link_name="shoulder_link"
			xyz_offset="0 0 0"
			rpy_offset="0 0 0"
			mesh_package="niryo_one_description"
			mesh_name="shoulder_link"
		/>

		<xacro:create_link
			link_name="arm_link"
			xyz_offset="0 0 0"
			rpy_offset="0 0 0"
			mesh_package="niryo_one_description"
			mesh_name="arm_link"
		/>

		<xacro:create_link
			link_name="elbow_link"
			xyz_offset="0 0 0"
			rpy_offset="0 0 0"
			mesh_package="niryo_one_description"
			mesh_name="elbow_link"
		/>

		<xacro:create_link
			link_name="forearm_link"
			xyz_offset="0 0 0"
			rpy_offset="0 0 0"
			mesh_package="niryo_one_description"
			mesh_name="forearm_link"
		/>

		<xacro:create_link
			link_name="wrist_link"
			xyz_offset="0 0 0"
			rpy_offset="0 0 0"
			mesh_package="niryo_one_description"
			mesh_name="wrist_link"
		/>

		<xacro:create_link
			link_name="hand_link"
			xyz_offset="0 0 0"
			rpy_offset="0 0 0"
			mesh_package="niryo_one_description"
			mesh_name="hand_link"
		/>

		<link name="tool_link" />

		<!--Joints -->
		<joint name="base_joint" type="fixed">
			<parent link="world" />
			<child link="base_link" />
			<origin xyz="0 0 0" rpy="0 0 0" />
			<axis xyz="0 0 1" />
		</joint>

		<joint name="joint_1" type="revolute">
			<parent link="base_link" />
			<child link="shoulder_link" />
			<origin xyz="0 0 ${distance_origin_shoulder_z}" rpy="0 0 0" />
			<axis xyz="0 0 1" />
			<limit effort="1" velocity="1.0" lower="${limit_low_shoulder_rotation}" upper="${limit_up_shoulder_rotation}" />
		</joint>

		<joint name="joint_2" type="revolute">
			<parent link="shoulder_link" />
			<child link="arm_link" />
			<origin xyz="0 0 ${distance_shoulder_arm_z}" rpy="${PI/2} ${-PI/2} 0" />
			<limit effort="1" velocity="1.0" lower="${limit_low_arm_rotation}" upper="${limit_up_arm_rotation}" />
			<axis xyz="0 0 1" />
		</joint>

		<joint name="joint_3" type="revolute">
			<parent link="arm_link" />
			<child link="elbow_link" />
			<origin xyz="${distance_arm_elbow_x} ${distance_arm_elbow_y} 0" rpy="0 0 ${-PI/2}" />
			<limit effort="1" velocity="1.0" lower="${limit_low_elbow_rotation}" upper="${limit_up_elbow_rotation}" />
			<axis xyz="0 0 1" />
		</joint>

		<joint name="joint_4" type="revolute">
			<parent link="elbow_link" />
			<child link="forearm_link" />
			<origin xyz="${distance_elbow_forearm_x} ${distance_elbow_forearm_y} 0" rpy="0 ${PI/2} 0" />
			<limit effort="1" velocity="1.0" lower="${limit_low_forearm_rotation}" upper="${limit_up_forearm_rotation}" />
			<axis xyz="0 0 1" />
		</joint>

		<joint name="joint_5" type="revolute">
			<parent link="forearm_link" />
			<child link="wrist_link" />
			<origin xyz="0 0 ${distance_forearm_wrist_z}" rpy="0 ${-PI/2} 0" />
			<limit effort="1" velocity="1.0" lower="${limit_low_wrist_rotation}" upper="${limit_up_wrist_rotation}" />
			<axis xyz="0 0 1" />
		</joint>

		<joint name="joint_6" type="revolute">
			<parent link="wrist_link" />
			<child link="hand_link" />
			<origin xyz="${distance_wrist_hand_x} ${distance_wrist_hand_y} 0" rpy="0 ${PI/2} 0" />
			<limit effort="1" velocity="1.0" lower="${limit_low_hand_rotation}" upper="${limit_up_hand_rotation}" />
			<axis xyz="0 0 1" />
		</joint>

		<joint name="hand_tool_joint" type="fixed">
			<parent link="hand_link" />
			<child link="tool_link" />
			<origin xyz="0 0 ${distance_hand_tool}" rpy="${-PI/2} ${-PI/2} 0" />
		</joint>
	</xacro:macro>
</robot>
